# Why does uncaught exception get logged to Sentry twice?
app.run(debug=True)
to
app.run(debug=False)
